//package jp02;
/*
 * java ExceptionTest 10 20 0실행시 3번째 인자값이 0이면 실행시 문제발생
 *==>출력결과(실행시 에러)읽고 출력결과 확인
 *==>해결 1. try{} catch로 문제 Exception예외)발생상황 처리, 정상 종료
 */
public class ExceptionTest03 {
	//Field
	private int sum;
	private int avg;
	
	//Construtor
	public ExceptionTest03() {
		
	}
	//Mehtod
	public void sum(int x, int y) {
		System.out.println("1.==> sum 시작");
		sum = x+y;
		System.out.println("1.==>합:"+sum);
		System.out.println("1.==> sum 끝");
	}
	//JVM에서 던진 ArithmethicException을 다시 자신을 호출한 곳으로 던진다
	public void avg(int z) {
		System.out.println("2.==> avg 시작");
		//z==0인경우 불능
		avg = sum/z;
		System.out.println("2.==> 평균: "+avg);
		System.out.println("2==> avg 끝");
	}
	
	//main method
	public static void main(String[] args) {
		int i = Integer.parseInt(args[0]);
		int j = Integer.parseInt(args[1]);
		int k = Integer.parseInt(args[2]);
		
		ExceptionTest03 et = new ExceptionTest03();
		et.sum(i,j);
		
		//==>어떤 Exception이 발생하는지 확인하자
		et.avg(k);
		System.out.println("main Method End");
	}//end of main
}// end of class
